2024-04-08 10:51:48,140 INFO    StreamThr :23316 [internal.py:wandb_internal():86] W&B internal server running at pid: 23316, started at: 2024-04-08 10:51:48.140790
2024-04-08 10:51:48,142 DEBUG   HandlerThread:23316 [handler.py:handle_request():146] handle_request: status
2024-04-08 10:51:48,150 INFO    WriterThread:23316 [datastore.py:open_for_write():87] open: E:\Projects\CLIP\wandb\run-20240408_105148-9mkwmn82\run-9mkwmn82.wandb
2024-04-08 10:51:48,150 DEBUG   SenderThread:23316 [sender.py:send():379] send: header
2024-04-08 10:51:48,188 DEBUG   SenderThread:23316 [sender.py:send():379] send: run
2024-04-08 10:51:49,755 ERROR   SenderThread:23316 [internal_api.py:execute():373] 404 response executing GraphQL.
2024-04-08 10:51:49,767 ERROR   SenderThread:23316 [internal_api.py:execute():374] {"errors":[{"message":"entity Gengsheng Li not found during upsertBucket","path":["upsertBucket"]}],"data":{"upsertBucket":null}}
2024-04-08 10:51:49,774 ERROR   SenderThread:23316 [sender.py:send_run():971] It appears that you do not have permission to access the requested resource. Please reach out to the project owner to grant you access. If you have the correct permissions, verify that there are no issues with your networking setup.(Error 404: Not Found)
Traceback (most recent call last):
  File "D:\Anaconda\envs\pytorch0\lib\site-packages\wandb\sdk\lib\retry.py", line 131, in __call__
    result = self._call_fn(*args, **kwargs)
  File "D:\Anaconda\envs\pytorch0\lib\site-packages\wandb\sdk\internal\internal_api.py", line 369, in execute
    return self.client.execute(*args, **kwargs)  # type: ignore
  File "D:\Anaconda\envs\pytorch0\lib\site-packages\wandb\vendor\gql-0.2.0\wandb_gql\client.py", line 52, in execute
    result = self._get_result(document, *args, **kwargs)
  File "D:\Anaconda\envs\pytorch0\lib\site-packages\wandb\vendor\gql-0.2.0\wandb_gql\client.py", line 60, in _get_result
    return self.transport.execute(document, *args, **kwargs)
  File "D:\Anaconda\envs\pytorch0\lib\site-packages\wandb\sdk\lib\gql_request.py", line 59, in execute
    request.raise_for_status()
  File "D:\Anaconda\envs\pytorch0\lib\site-packages\requests\models.py", line 1021, in raise_for_status
    raise HTTPError(http_error_msg, response=self)
requests.exceptions.HTTPError: 404 Client Error: Not Found for url: https://api.wandb.ai/graphql

During handling of the above exception, another exception occurred:

Traceback (most recent call last):
  File "D:\Anaconda\envs\pytorch0\lib\site-packages\wandb\sdk\internal\sender.py", line 969, in send_run
    server_run = self._init_run(run, config_value_dict)
  File "D:\Anaconda\envs\pytorch0\lib\site-packages\wandb\sdk\internal\sender.py", line 1014, in _init_run
    server_run, inserted, server_messages = self._api.upsert_run(
  File "D:\Anaconda\envs\pytorch0\lib\site-packages\wandb\apis\normalize.py", line 73, in wrapper
    raise err
  File "D:\Anaconda\envs\pytorch0\lib\site-packages\wandb\apis\normalize.py", line 41, in wrapper
    return func(*args, **kwargs)
  File "D:\Anaconda\envs\pytorch0\lib\site-packages\wandb\sdk\internal\internal_api.py", line 2217, in upsert_run
    response = self.gql(
  File "D:\Anaconda\envs\pytorch0\lib\site-packages\wandb\sdk\internal\internal_api.py", line 341, in gql
    ret = self._retry_gql(
  File "D:\Anaconda\envs\pytorch0\lib\site-packages\wandb\sdk\lib\retry.py", line 147, in __call__
    retry_timedelta_triggered = check_retry_fn(e)
  File "D:\Anaconda\envs\pytorch0\lib\site-packages\wandb\util.py", line 968, in check_retry_fn
    return fallback_retry_fn(e)
  File "D:\Anaconda\envs\pytorch0\lib\site-packages\wandb\util.py", line 910, in no_retry_auth
    raise CommError(
wandb.errors.CommError: It appears that you do not have permission to access the requested resource. Please reach out to the project owner to grant you access. If you have the correct permissions, verify that there are no issues with your networking setup.(Error 404: Not Found)
2024-04-08 10:51:50,725 DEBUG   HandlerThread:23316 [handler.py:handle_request():146] handle_request: shutdown
2024-04-08 10:51:50,725 INFO    HandlerThread:23316 [handler.py:finish():866] shutting down handler
2024-04-08 10:51:50,791 INFO    SenderThread:23316 [sender.py:finish():1546] shutting down sender
2024-04-08 10:51:51,212 INFO    WriterThread:23316 [datastore.py:close():296] close: E:\Projects\CLIP\wandb\run-20240408_105148-9mkwmn82\run-9mkwmn82.wandb
